<?xml version="1.0" ?>
<sdf version='1.11'>
  <model name='prius'>
    <link name='base_link'>
      <inertial>
        <pose>0 0 0 0 0 0</pose>
        <mass>1</mass>
        <inertia>
          <ixx>0.001</ixx>
          <ixy>0</ixy>
          <ixz>0</ixz>
          <iyy>0.001</iyy>
          <iyz>0</iyz>
          <izz>0.001</izz>
        </inertia>
      </inertial>
    </link>
    <joint name='base_link_connection' type='revolute'>
      <pose relative_to='base_link'>1.45 0 0 0 0 1.5700000000000001</pose>
      <parent>base_link</parent>
      <child>chassis</child>
      <axis>
        <limit>
          <lower>0</lower>
          <upper>0</upper>
        </limit>
        <dynamics>
          <damping>0</damping>
          <friction>0</friction>
          <spring_reference>0</spring_reference>
          <spring_stiffness>0</spring_stiffness>
        </dynamics>
        <xyz>0 0 1</xyz>
      </axis>
      <physics>
        <ode>
          <limit>
            <cfm>0</cfm>
            <erp>0.20000000000000001</erp>
          </limit>
        </ode>
      </physics>
    </joint>
    <link name='chassis'>
      <pose relative_to='base_link_connection'>0 0 0 0 0 0</pose>
      <inertial>
        <pose>0 -0.002981818181818181 0.48529454545454531 0 0 1.5708</pose>
        <mass>1375</mass>
        <inertia>
          <ixx>2595.5180031097761</ixx>
          <ixy>0.0001890318568118954</ixy>
          <ixz>-0.94970763635722444</ixz>
          <iyy>657.15529137384988</iyy>
          <iyz>3.4884709365781031e-06</iyz>
          <izz>2749.8122608254548</izz>
        </inertia>
      </inertial>
      <collision name='chassis_collision'>
        <pose>0 0.050000000000000003 0.625 0 0 0</pose>
        <geometry>
          <box>
            <size>1.7525999999999999 2.1000000000000001 0.94999999999999996</size>
          </box>
        </geometry>
      </collision>
      <collision name='chassis_fixed_joint_lump__front_bumper_collision_1'>
        <pose>0 -2 0.45848800000000001 0 0 0</pose>
        <geometry>
          <box>
            <size>1.3372820000000001 0.47999999999999998 0.56669099999999994</size>
          </box>
        </geometry>
      </collision>
      <collision name='chassis_fixed_joint_lump__hood_collision_2'>
        <pose>0 -1.9008419999999999 0.67630500000000005 0.34124700000000013 0 0</pose>
        <geometry>
          <box>
            <size>1.5979680000000001 0.49310700000000002 0.26546799999999998</size>
          </box>
        </geometry>
      </collision>
      <collision name='chassis_fixed_joint_lump__windshield_collision_3'>
        <pose>0 -0.87510500000000002 1.032268 0.335476 0 0</pose>
        <geometry>
          <box>
            <size>1.1683809999999999 1.654253 0.27234700000000001</size>
          </box>
        </geometry>
      </collision>
      <collision name='chassis_fixed_joint_lump__top_front_collision_4'>
        <pose>0 0.16123599999999999 1.386042 0.13503000000000004 0 0</pose>
        <geometry>
          <box>
            <size>1.2791539999999999 0.62598799999999999 0.17186799999999999</size>
          </box>
        </geometry>
      </collision>
      <collision name='chassis_fixed_joint_lump__top_rear_collision_5'>
        <pose>0 0.81769599999999998 1.360069 -0.068997000000000003 0 0</pose>
        <geometry>
          <box>
            <size>1.2851300000000001 0.77118900000000001 0.22655700000000001</size>
          </box>
        </geometry>
      </collision>
      <collision name='chassis_fixed_joint_lump__rear_window_collision_6'>
        <pose>0 1.640531 1.1751259999999999 -0.26201699999999983 0 0</pose>
        <geometry>
          <box>
            <size>1.2678450000000001 1.116344 0.244286</size>
          </box>
        </geometry>
      </collision>
      <collision name='chassis_fixed_joint_lump__trunk_collision_7'>
        <pose>0 1.637059 0.88817999999999997 0 0 0</pose>
        <geometry>
          <box>
            <size>1.7880640000000001 1.1389879999999999 0.48274600000000001</size>
          </box>
        </geometry>
      </collision>
      <collision name='chassis_fixed_joint_lump__back_bumper_collision_8'>
        <pose>0 2.0544539999999998 0.57786999999999999 0 0 0</pose>
        <geometry>
          <box>
            <size>1.78165 0.51209300000000002 0.58142700000000003</size>
          </box>
        </geometry>
      </collision>
      <visual name='chassis_visual'>
        <pose>0 0 0 0 0 0</pose>
        <geometry>
          <mesh>
            <scale>0.01 0.01 0.01</scale>
            <uri>/home/piyush/chall_ws/src/roshai_pkgs/roshai_gazebo/meshes/hybrid_body.obj</uri>
          </mesh>
        </geometry>
      </visual>
      <visual name='chassis_fixed_joint_lump__center_laser_link_visual_1'>
        <pose>0 0.40000000000000002 1.8 0 0 -1.5707</pose>
        <geometry>
          <box>
            <size>0.10000000000000001 0.10000000000000001 0.10000000000000001</size>
          </box>
        </geometry>
      </visual>
      <sensor name="center_laser_link_sensorI" type="gpu_lidar">
        <pose relative_to='center_laser_link'>0 0 0 0 0 0</pose>
        <always_on>true</always_on>
        <visualize>true</visualize>
        <update_rate>5</update_rate>
        <topic>center_scan</topic>
        <gz_frame_id>center_laser_link</gz_frame_id>
        <lidar>
          <scan>
            <horizontal>
              <samples>360</samples>
              <resolution>1.000000</resolution>
              <min_angle>0.000000</min_angle>
              <max_angle>6.280000</max_angle>
            </horizontal>
          </scan>
          <range>
            <min>0.120000</min>
            <max>3.5</max>
            <resolution>0.015000</resolution>
          </range>
          <noise>
            <type>gaussian</type>
            <mean>0.0</mean>
            <stddev>0.01</stddev>
          </noise>
        </lidar>
      </sensor>
      
        <sensor name="center_laser_link_imu" type="imu">
          <pose relative_to='center_laser_link'>0 0 0 0 0 0</pose>
          <always_on>true</always_on>
          <update_rate>200</update_rate>
          <topic>imu</topic>
          <imu>
            <angular_velocity>
              <x>
                <noise type="gaussian">
                  <mean>0.0</mean>
                  <stddev>2e-4</stddev>
                </noise>
              </x>
              <y>
                <noise type="gaussian">
                  <mean>0.0</mean>
                  <stddev>2e-4</stddev>
                </noise>
              </y>
              <z>
                <noise type="gaussian">
                  <mean>0.0</mean>
                  <stddev>2e-4</stddev>
                </noise>
              </z>
            </angular_velocity>
            <linear_acceleration>
              <x>
                <noise type="gaussian">
                  <mean>0.0</mean>
                  <stddev>1.7e-2</stddev>
                </noise>
              </x>
              <y>
                <noise type="gaussian">
                  <mean>0.0</mean>
                  <stddev>1.7e-2</stddev>
                </noise>
              </y>
              <z>
                <noise type="gaussian">
                  <mean>0.0</mean>
                  <stddev>1.7e-2</stddev>
                </noise>
              </z>
            </linear_acceleration>
          </imu>
        </sensor>
        <sensor name="camera" type="camera">
          <pose relative_to='center_laser_link'>0 0 0 0 0 0</pose>
          <always_on>true</always_on>
          <visualize>true</visualize>
          <update_rate>30</update_rate>
          <topic>camera/image_raw</topic>
          <gz_frame_id>center_laser_link</gz_frame_id>
          <camera name="intel_realsense_r200">
            <camera_info_topic>camera/camera_info</camera_info_topic>
            <horizontal_fov>1.02974</horizontal_fov>
            <image>
              <width>1920</width>
              <height>1080</height>
              <format>R8G8B8</format>
            </image>
            <clip>
              <near>0.02</near>
              <far>300</far>
            </clip>
            <noise>
              <type>gaussian</type>
              <!-- Noise is sampled independently per pixel on each frame.
                    That pixel's noise value is added to each of its color
                    channels, which at that point lie in the range [0,1]. -->
              <mean>0.0</mean>
              <stddev>0.007</stddev>
            </noise>
          </camera>
        </sensor>
    </link>
    <joint name='front_left_steer_joint' type='revolute'>
      <pose relative_to='chassis'>0.76700000000000002 -1.4099999999999999 0.29999999999999999 0 0 0</pose>
      <parent>chassis</parent>
      <child>fl_axle</child>
      <axis>
        <xyz>0 0 1</xyz>
        <limit>
          <effort>10000000</effort>
          <velocity>1000000</velocity>
          <lower>-inf</lower>
          <upper>inf</upper>
        </limit>
        <dynamics>
          <spring_reference>0</spring_reference>
          <spring_stiffness>0</spring_stiffness>
        </dynamics>
      </axis>
    </joint>
    <link name='fl_axle'>
      <pose relative_to='front_left_steer_joint'>0 0 0 0 0 0</pose>
      <inertial>
        <pose>0 0 0 0 0 0</pose>
        <mass>1</mass>
        <inertia>
          <ixx>0.0040000000000000001</ixx>
          <ixy>0</ixy>
          <ixz>0</ixz>
          <iyy>0.0040000000000000001</iyy>
          <iyz>0</iyz>
          <izz>0.0040000000000000001</izz>
        </inertia>
      </inertial>
    </link>
    <joint name='front_left_wheel_joint' type='revolute'>
      <pose relative_to='fl_axle'>0 0 0 0 0 0</pose>
      <parent>fl_axle</parent>
      <child>front_left_wheel</child>
      <axis>
        <xyz>1 0 0</xyz>
        <limit>
          <lower>-inf</lower>
          <upper>inf</upper>
        </limit>
        <dynamics>
          <spring_reference>0</spring_reference>
          <spring_stiffness>0</spring_stiffness>
        </dynamics>
      </axis>
    </joint>
    <link name='front_left_wheel'>
      <pose relative_to='front_left_wheel_joint'>0 0 0 0 0 0</pose>
      <inertial>
        <pose>0 0 0 0 0 0</pose>
        <mass>11</mass>
        <inertia>
          <ixx>0.58631237999999997</ixx>
          <ixy>0</ixy>
          <ixz>0</ixz>
          <iyy>0.33552910000000002</iyy>
          <iyz>0</iyz>
          <izz>0.33552910000000002</izz>
        </inertia>
      </inertial>
      <collision name='front_left_wheel_collision_collision'>
        <pose>0 0 0 0 0 0</pose>
        <geometry>
          <sphere>
            <radius>0.31264999999999998</radius>
          </sphere>
        </geometry>
        <surface>
          <contact>
            <ode>
              <kp>100000000</kp>
              <min_depth>0.0050000000000000001</min_depth>
            </ode>
          </contact>
          <friction>
            <ode>
              <mu>0.90000000000000002</mu>
              <mu2>0.90000000000000002</mu2>
            </ode>
          </friction>
        </surface>
      </collision>
      <visual name='front_left_wheel_visual'>
        <pose>0 0 0 0 0 0</pose>
        <geometry>
          <mesh>
            <scale>0.01 0.01 0.01</scale>
            <uri>/home/piyush/chall_ws/src/roshai_pkgs/roshai_gazebo/meshes/wheel.obj</uri>
          </mesh>
        </geometry>
      </visual>
    </link>
    <joint name='front_right_steer_joint' type='revolute'>
      <pose relative_to='chassis'>-0.76700000000000002 -1.4099999999999999 0.29999999999999999 0 0 0</pose>
      <parent>chassis</parent>
      <child>fr_axle</child>
      <axis>
        <xyz>0 0 1</xyz>
        <limit>
          <effort>10000000</effort>
          <velocity>1000000</velocity>
          <lower>-inf</lower>
          <upper>inf</upper>
        </limit>
        <dynamics>
          <spring_reference>0</spring_reference>
          <spring_stiffness>0</spring_stiffness>
        </dynamics>
      </axis>
    </joint>
    <link name='fr_axle'>
      <pose relative_to='front_right_steer_joint'>0 0 0 0 0 0</pose>
      <inertial>
        <pose>0 0 0 0 0 0</pose>
        <mass>1</mass>
        <inertia>
          <ixx>0.0040000000000000001</ixx>
          <ixy>0</ixy>
          <ixz>0</ixz>
          <iyy>0.0040000000000000001</iyy>
          <iyz>0</iyz>
          <izz>0.0040000000000000001</izz>
        </inertia>
      </inertial>
    </link>
    <joint name='front_right_wheel_joint' type='revolute'>
      <pose relative_to='fr_axle'>0 0 0 0 0 0</pose>
      <parent>fr_axle</parent>
      <child>front_right_wheel</child>
      <axis>
        <xyz>1 0 0</xyz>
        <limit>
          <lower>-inf</lower>
          <upper>inf</upper>
        </limit>
        <dynamics>
          <spring_reference>0</spring_reference>
          <spring_stiffness>0</spring_stiffness>
        </dynamics>
      </axis>
    </joint>
    <link name='front_right_wheel'>
      <pose relative_to='front_right_wheel_joint'>0 0 0 0 0 0</pose>
      <inertial>
        <pose>0 0 0 0 0 0</pose>
        <mass>11</mass>
        <inertia>
          <ixx>0.58631237999999997</ixx>
          <ixy>0</ixy>
          <ixz>0</ixz>
          <iyy>0.33552910000000002</iyy>
          <iyz>0</iyz>
          <izz>0.33552910000000002</izz>
        </inertia>
      </inertial>
      <collision name='front_right_wheel_collision_collision'>
        <pose>0 0 0 0 0 0</pose>
        <geometry>
          <sphere>
            <radius>0.31264999999999998</radius>
          </sphere>
        </geometry>
        <surface>
          <contact>
            <ode>
              <kp>100000000</kp>
              <min_depth>0.0050000000000000001</min_depth>
            </ode>
          </contact>
          <friction>
            <ode>
              <mu>0.90000000000000002</mu>
              <mu2>0.90000000000000002</mu2>
            </ode>
          </friction>
        </surface>
      </collision>
      <visual name='front_right_wheel_visual'>
        <pose>0 0 0 0 0 0</pose>
        <geometry>
          <mesh>
            <scale>0.01 0.01 0.01</scale>
            <uri>/home/piyush/chall_ws/src/roshai_pkgs/roshai_gazebo/meshes/wheel.obj</uri>
          </mesh>
        </geometry>
      </visual>
    </link>
    <joint name='rear_left_wheel_joint' type='revolute'>
      <pose relative_to='chassis'>0.79300000000000004 1.45 0.29999999999999999 0 0 0</pose>
      <parent>chassis</parent>
      <child>rear_left_wheel</child>
      <axis>
        <xyz>1 0 0</xyz>
        <limit>
          <lower>-inf</lower>
          <upper>inf</upper>
        </limit>
        <dynamics>
          <spring_reference>0</spring_reference>
          <spring_stiffness>0</spring_stiffness>
        </dynamics>
      </axis>
    </joint>
    <link name='rear_left_wheel'>
      <pose relative_to='rear_left_wheel_joint'>0 0 0 0 0 0</pose>
      <inertial>
        <pose>0 0 0 0 0 0</pose>
        <mass>11</mass>
        <inertia>
          <ixx>0.58631237999999997</ixx>
          <ixy>0</ixy>
          <ixz>0</ixz>
          <iyy>0.33552910000000002</iyy>
          <iyz>0</iyz>
          <izz>0.33552910000000002</izz>
        </inertia>
      </inertial>
      <collision name='rear_left_wheel_collision_collision'>
        <pose>0 0 0 0 0 0</pose>
        <geometry>
          <sphere>
            <radius>0.31264999999999998</radius>
          </sphere>
        </geometry>
        <surface>
          <contact>
            <ode>
              <kp>100000000</kp>
              <min_depth>0.0050000000000000001</min_depth>
            </ode>
          </contact>
          <friction>
            <ode>
              <mu>0.90000000000000002</mu>
              <mu2>0.90000000000000002</mu2>
            </ode>
          </friction>
        </surface>
      </collision>
      <visual name='rear_left_wheel_visual'>
        <pose>0 0 0 0 0 0</pose>
        <geometry>
          <mesh>
            <scale>0.01 0.01 0.01</scale>
            <uri>/home/piyush/chall_ws/src/roshai_pkgs/roshai_gazebo/meshes/wheel.obj</uri>
          </mesh>
        </geometry>
      </visual>
    </link>
    <joint name='rear_right_wheel_joint' type='revolute'>
      <pose relative_to='chassis'>-0.79300000000000004 1.45 0.29999999999999999 0 0 0</pose>
      <parent>chassis</parent>
      <child>rear_right_wheel</child>
      <axis>
        <xyz>1 0 0</xyz>
        <limit>
          <lower>-inf</lower>
          <upper>inf</upper>
        </limit>
        <dynamics>
          <spring_reference>0</spring_reference>
          <spring_stiffness>0</spring_stiffness>
        </dynamics>
      </axis>
    </joint>
    <link name='rear_right_wheel'>
      <pose relative_to='rear_right_wheel_joint'>0 0 0 0 0 0</pose>
      <inertial>
        <pose>0 0 0 0 0 0</pose>
        <mass>11</mass>
        <inertia>
          <ixx>0.58631237999999997</ixx>
          <ixy>0</ixy>
          <ixz>0</ixz>
          <iyy>0.33552910000000002</iyy>
          <iyz>0</iyz>
          <izz>0.33552910000000002</izz>
        </inertia>
      </inertial>
      <collision name='rear_right_wheel_collision_collision'>
        <pose>0 0 0 0 0 0</pose>
        <geometry>
          <sphere>
            <radius>0.31264999999999998</radius>
          </sphere>
        </geometry>
        <surface>
          <contact>
            <ode>
              <kp>100000000</kp>
              <min_depth>0.0050000000000000001</min_depth>
            </ode>
          </contact>
          <friction>
            <ode>
              <mu>0.90000000000000002</mu>
              <mu2>0.90000000000000002</mu2>
            </ode>
          </friction>
        </surface>
      </collision>
      <visual name='rear_right_wheel_visual'>
        <pose>0 0 0 0 0 0</pose>
        <geometry>
          <mesh>
            <scale>0.01 0.01 0.01</scale>
            <uri>/home/piyush/chall_ws/src/roshai_pkgs/roshai_gazebo/meshes/wheel.obj</uri>
          </mesh>
        </geometry>
      </visual>
    </link>
    <joint name='steering_joint' type='revolute'>
      <pose relative_to='chassis'>0.357734 -0.62786799999999998 0.98824299999999998 -1.302101 0 0</pose>
      <parent>chassis</parent>
      <child>steering_wheel</child>
      <axis>
        <xyz>0 0 1</xyz>
        <limit>
          <effort>10000000</effort>
          <velocity>1000000</velocity>
          <lower>-inf</lower>
          <upper>inf</upper>
        </limit>
        <dynamics>
          <spring_reference>0</spring_reference>
          <spring_stiffness>0</spring_stiffness>
        </dynamics>
      </axis>
    </joint>
    <link name='steering_wheel'>
      <pose relative_to='steering_joint'>0 0 0 0 0 0</pose>
      <inertial>
        <pose>0 0 0 0 0 0</pose>
        <mass>1</mass>
        <inertia>
          <ixx>0.14583299999999999</ixx>
          <ixy>0</ixy>
          <ixz>0</ixz>
          <iyy>0.14583299999999999</iyy>
          <iyz>0</iyz>
          <izz>0.125</izz>
        </inertia>
      </inertial>
      <visual name='steering_wheel_visual'>
        <pose>0 0 0 1.302101 0 0</pose>
        <geometry>
          <mesh>
            <scale>0.01 0.01 0.01</scale>
            <uri>/home/piyush/chall_ws/src/roshai_pkgs/roshai_gazebo/meshes/steering_wheel.obj</uri>
          </mesh>
        </geometry>
      </visual>
    </link>
    <frame name='back_camera_optical_joint' attached_to='back_camera_link'>
      <pose>0 0 0 -1.5707 5.5511151231257827e-17 -1.5707</pose>
    </frame>
    <frame name='back_camera_link_optical' attached_to='back_camera_optical_joint'>
      <pose>0 0 0 0 0 0</pose>
    </frame>
    <frame name='back_camera_joint' attached_to='chassis'>
      <pose>0 1.45 1.3999999999999999 0 0.050000000000000003 1.5707</pose>
    </frame>
    <frame name='back_camera_link' attached_to='back_camera_joint'>
      <pose>0 0 0 0 0 0</pose>
    </frame>
    <frame name='back_left_far_sonar_joint' attached_to='chassis'>
      <pose>0.69999999999999996 2.3999999999999999 0.5 0 0 1.5707</pose>
    </frame>
    <frame name='back_left_far_sonar_link' attached_to='back_left_far_sonar_joint'>
      <pose>0 0 0 0 0 0</pose>
    </frame>
    <frame name='back_left_middle_sonar_joint' attached_to='chassis'>
      <pose>0.23999999999999999 2.3999999999999999 0.5 0 0 1.5707</pose>
    </frame>
    <frame name='back_left_middle_sonar_link' attached_to='back_left_middle_sonar_joint'>
      <pose>0 0 0 0 0 0</pose>
    </frame>
    <frame name='back_right_far_sonar_joint' attached_to='chassis'>
      <pose>-0.69999999999999996 2.3999999999999999 0.5 0 0 1.5707</pose>
    </frame>
    <frame name='back_right_far_sonar_link' attached_to='back_right_far_sonar_joint'>
      <pose>0 0 0 0 0 0</pose>
    </frame>
    <frame name='back_right_middle_sonar_joint' attached_to='chassis'>
      <pose>-0.23999999999999999 2.3999999999999999 0.5 0 0 1.5707</pose>
    </frame>
    <frame name='back_right_middle_sonar_link' attached_to='back_right_middle_sonar_joint'>
      <pose>0 0 0 0 0 0</pose>
    </frame>
    <frame name='center_laser_joint' attached_to='chassis'>
      <pose>0 0.40000000000000002 1.8 0 0 -1.5707</pose>
    </frame>
    <frame name='center_laser_link' attached_to='center_laser_joint'>
      <pose>0 0 0 0 0 0</pose>
    </frame>
    <frame name='front_camera_optical_joint' attached_to='front_camera_link'>
      <pose>0 0 0 -1.5707 5.5511151231257827e-17 -1.5707</pose>
    </frame>
    <frame name='front_camera_link_optical' attached_to='front_camera_optical_joint'>
      <pose>0 0 0 0 0 0</pose>
    </frame>
    <frame name='front_camera_joint' attached_to='chassis'>
      <pose>0 -0.40000000000000002 1.3999999999999999 0 0.050000000000000003 -1.5707</pose>
    </frame>
    <frame name='front_camera_link' attached_to='front_camera_joint'>
      <pose>0 0 0 0 0 0</pose>
    </frame>
    <frame name='front_left_far_sonar_joint' attached_to='chassis'>
      <pose>0.69999999999999996 -2.1000000000000001 0.5 0 0 -1.5707</pose>
    </frame>
    <frame name='front_left_far_sonar_link' attached_to='front_left_far_sonar_joint'>
      <pose>0 0 0 0 0 0</pose>
    </frame>
    <frame name='front_left_laser_joint' attached_to='chassis'>
      <pose>1 -2.2999999999999998 0.5 0 0.050000000000000003 0</pose>
    </frame>
    <frame name='front_left_laser_link' attached_to='front_left_laser_joint'>
      <pose>0 0 0 0 0 0</pose>
    </frame>
    <frame name='front_left_middle_sonar_joint' attached_to='chassis'>
      <pose>0.23999999999999999 -2.2999999999999998 0.5 0 0 -1.5707</pose>
    </frame>
    <frame name='front_left_middle_sonar_link' attached_to='front_left_middle_sonar_joint'>
      <pose>0 0 0 0 0 0</pose>
    </frame>
    <frame name='front_right_far_sonar_joint' attached_to='chassis'>
      <pose>-0.69999999999999996 -2.1000000000000001 0.5 0 0 -1.5707</pose>
    </frame>
    <frame name='front_right_far_sonar_link' attached_to='front_right_far_sonar_joint'>
      <pose>0 0 0 0 0 0</pose>
    </frame>
    <frame name='front_right_laser_joint' attached_to='chassis'>
      <pose>-1 -2.2999999999999998 0.5 -2.0354228219238686e-20 0.050000000000000024 3.1400000000000001</pose>
    </frame>
    <frame name='front_right_laser_link' attached_to='front_right_laser_joint'>
      <pose>0 0 0 0 0 0</pose>
    </frame>
    <frame name='front_right_middle_sonar_joint' attached_to='chassis'>
      <pose>-0.23999999999999999 -2.2999999999999998 0.5 0 0 -1.5707</pose>
    </frame>
    <frame name='front_right_middle_sonar_link' attached_to='front_right_middle_sonar_joint'>
      <pose>0 0 0 0 0 0</pose>
    </frame>
    <frame name='left_camera_optical_joint' attached_to='left_camera_link'>
      <pose>0 0 0 -1.5707 5.5511151231257827e-17 -1.5707</pose>
    </frame>
    <frame name='left_camera_link_optical' attached_to='left_camera_optical_joint'>
      <pose>0 0 0 0 0 0</pose>
    </frame>
    <frame name='left_camera_joint' attached_to='chassis'>
      <pose>1 -0.69999999999999996 1 0 0.050000000000000003 1</pose>
    </frame>
    <frame name='left_camera_link' attached_to='left_camera_joint'>
      <pose>0 0 0 0 0 0</pose>
    </frame>
    <frame name='right_camera_optical_joint' attached_to='right_camera_link'>
      <pose>0 0 0 -1.5707 5.5511151231257827e-17 -1.5707</pose>
    </frame>
    <frame name='right_camera_link_optical' attached_to='right_camera_optical_joint'>
      <pose>0 0 0 0 0 0</pose>
    </frame>
    <frame name='right_camera_joint' attached_to='chassis'>
      <pose>-1 -0.69999999999999996 1 0 0.050000000000000003 2.1415999999999999</pose>
    </frame>
    <frame name='right_camera_link' attached_to='right_camera_joint'>
      <pose>0 0 0 0 0 0</pose>
    </frame>

   
    <plugin filename="gz-sim-diff-drive-system" name="gz::sim::systems::DiffDrive">
      <!-- wheels -->
      <left_joint>rear_left_wheel_joint</left_joint>
      <right_joint>rear_right_wheel_joint</right_joint>

      <!-- kinematics -->
      <wheel_separation>1.510</wheel_separation>
      <wheel_radius>0.215</wheel_radius>

      <!-- limits -->
      <max_linear_acceleration>1.0</max_linear_acceleration>

      <topic>cmd_vel</topic>


      <odom_topic>odom</odom_topic>
      <frame_id>odom</frame_id>
      <tf_topic>/tf</tf_topic>
      <odom_publisher_frequency>30</odom_publisher_frequency>
      <child_frame_id>base_link</child_frame_id>

    </plugin>

    <plugin filename="gz-sim-joint-state-publisher-system"
      name="gz::sim::systems::JointStatePublisher">
      <topic>joint_states</topic>
      <!-- <update_rate>30</update_rate> -->
      <joint_name>rear_left_wheel_joint</joint_name>
      <joint_name>rear_right_wheel_joint</joint_name>
    </plugin>    

  </model>
</sdf>
